Workbook

Sheet Model
B3: Vinci SA (DG FP) - BBG GAAP
A5: x | B5: In Millions of EUR except Per Share | C5: FY 2017 | D5: FY 2018 | E5: FY 2019 | F5: FY 2020 | G5: FY 2021 | H5: FY 2022 | I5: FY 2023 | J5: FY 2024 Est | K5: FY 2025 Est | L5: FY 2026 Est | M5: FY 2027 Est | N5: FY 2028 Est
B6: 12 Months Ending | C6: 12/31/2017 | D6: 12/31/2018 | E6: 12/31/2019 | F6: 12/31/2020 | G6: 12/31/2021 | H6: 12/31/2022 | I6: 12/31/2023 | J6: 12/31/2024 | K6: 12/31/2025
B7: Revenue | C7: 40876 | D7: 44152 | E7: 48752 | F7: 43930 | G7: 49982 | H7: 62265 | I7: 69618 | J7: ='Segment Rev+OPI build'!AI54 -> 72017.38 | K7: ='Segment Rev+OPI build'!AJ54 -> 74942.957 | L7: ='Segment Rev+OPI build'!AK54 -> 78102.056 | M7: ='Segment Rev+OPI build'!AL54 -> 81410.793 | N7: ='Segment Rev+OPI build'!AM54 -> 84877.136
B8: + Sales & Services Revenue | C8: 40876 | D8: 44152 | E8: 48053 | F8: 43234 | G8: 49396 | H8: 61675 | I8: 68838
B9: + Other Revenue | C9: — | D9: — | E9: 699 | F9: 696 | G9: 586 | H9: 590 | I9: 780
B10: + Other Operating Income | C10: 200 | D10: 202 | E10: 198 | F10: 188 | G10: 248 | H10: 249 | I10: 267
B11: - Operating Expenses | C11: 36672 | D11: 39522 | E11: 43498 | F11: 41513 | G11: 45805 | H11: 56048 | I11: 61926
B12: + Research & Development | C12: 0 | D12: 0 | E12: 0 | F12: 0 | G12: 0 | H12: 0 | I12: 0
B13: + Other Operating Expense | C13: 36672 | D13: 39522 | E13: 43498 | F13: 41513 | G13: 45805 | H13: 56048 | I13: 61926
B14: Operating Income (Loss) | C14: 4404 | D14: 4832 | E14: 5452 | F14: 2605 | G14: 4425 | H14: 6466 | I14: 7959 | J14: ='Segment Rev+OPI build'!AH56 -> 8357 | K14: ='Segment Rev+OPI build'!AI56 -> 8760.1266 | L14: ='Segment Rev+OPI build'!AJ56 -> 9153.3751 | M14: ='Segment Rev+OPI build'!AK56 -> 9570.8023 | N14: ='Segment Rev+OPI build'!AL56 -> 10009.934
B15: - Non-Operating (Income) Loss | C15: 296 | D15: 357 | E15: 410 | F15: 781 | G15: 605 | H15: 313 | I15: 940 | J15: =SUM(J16:J21) -> 818.986 | K15: =SUM(K16:K21) -> 833.96405 | L15: =SUM(L16:L21) -> 845.77186 | M15: =SUM(M16:M21) -> 884.34213 | N15: =SUM(N16:N21) -> 924.91789
B16: + Interest Expense, Net | C16: 597 | D16: 606 | E16: 753 | F16: 776 | G16: 766 | H16: 719 | I16: 743 | J16: =J157 -> 818.986 | K16: =K157 -> 833.96405 | L16: =L157 -> 845.77186 | M16: =M157 -> 884.34213 | N16: =N157 -> 924.91789
B17: + Interest Expense | C17: 653 | D17: 635 | E17: 794 | F17: 796 | G17: 767 | H17: 839 | I17: 1205
B18: - Interest Income | C18: 56 | D18: 29 | E18: 41 | F18: 20 | G18: 1 | H18: 120 | I18: 462
B19: + Foreign Exch (Gain) Loss | C19: 11 | D19: 9 | E19: -8 | F19: 15 | G19: -66 | H19: -43 | I19: 119 | J19: 0 | K19: 0 | L19: 0 | M19: 0 | N19: 0
B20: + (Income) Loss from Affiliates | C20: -146 | D20: -88 | E20: -212 | F20: 146 | G20: -12 | H20: -22 | I20: -111 | J20: 0 | K20: 0 | L20: 0 | M20: 0 | N20: 0
B21: + Other Non-Op (Income) Loss | C21: -166 | D21: -170 | E21: -123 | F21: -156 | G21: -83 | H21: -341 | I21: 189 | J21: 0 | K21: 0 | L21: 0 | M21: 0 | N21: 0
B22: Pretax Income | C22: 4108 | D22: 4475 | E22: 5042 | F22: 1824 | G22: 3820 | H22: 6153 | I22: =I14-I15 -> 7019 | J22: =J14-J15 -> 7538.014 | K22: =K14-K15 -> 7926.1625 | L22: =L14-L15 -> 8307.6033 | M22: =M14-M15 -> 8686.4602 | N22: =N14-N15 -> 9085.0159
B23: - Income Tax Expense (Benefit) | C23: 1271 | D23: 1418 | E23: 1634 | F23: 807 | G23: 1625 | H23: 1737 | I23: 1917 | J23: =J306 -> 2110.6439 | K23: =K306 -> 2219.3255 | L23: =L306 -> 2326.1289 | M23: =M306 -> 2432.2088 | N23: =N306 -> 2543.8045
B24: + Current Income Tax | C24: 1537 | D24: 1529 | E24: 1791 | F24: 844 | G24: 1509 | H24: 1809 | I24: 2332
B25: + Deferred Income Tax | C25: -266 | D25: -111 | E25: -157 | F25: -37 | G25: 116 | H25: -72 | I25: -415
B26: Income (Loss) from Cont Ops | C26: 2837 | D26: 3057 | E26: 3408 | F26: 1017 | G26: 2195 | H26: 4416 | I26: 5102 | J26: =J22-J23 -> 5427.3701 | K26: =K22-K23 -> 5706.837 | L26: =L22-L23 -> 5981.4743 | M26: =M22-M23 -> 6254.2513 | N26: =N22-N23 -> 6541.2115
B27: - Net Extraordinary Losses (Gains) | C27: 0 | D27: 0 | E27: 0 | F27: 0 | G27: 0 | H27: 0 | I27: 0 | J27: 0 | K27: 0 | L27: 0 | M27: 0 | N27: 0
B28: + Discontinued Operations | C28: 0 | D28: 0 | E28: 0 | F28: 0 | G28: 0 | H28: 0 | I28: 0 | J28: 0 | K28: 0 | L28: 0 | M28: 0 | N28: 0
B29: + XO & Accounting Changes | C29: 0 | D29: 0 | E29: 0 | F29: 0 | G29: 0 | H29: 0 | I29: 0 | J29: 0 | K29: 0 | L29: 0 | M29: 0 | N29: 0
B30: Income (Loss) Incl. MI | C30: 2837 | D30: 3057 | E30: 3408 | F30: 1017 | G30: 2195 | H30: 4416 | I30: 5102 | J30: =J26-SUM(J27:J29) -> 5427.3701 | K30: =K26-SUM(K27:K29) -> 5706.837 | L30: =L26-SUM(L27:L29) -> 5981.4743 | M30: =M26-SUM(M27:M29) -> 6254.2513 | N30: =N26-SUM(N27:N29) -> 6541.2115
B31: - Minority Interest | C31: 90 | D31: 74 | E31: 148 | F31: -226 | G31: -402 | H31: 157 | I31: 400 | J31: 400 | K31: 400 | L31: 400 | M31: 400 | N31: 401
B32: Net Income, GAAP | C32: 2747 | D32: 2983 | E32: 3260 | F32: 1243 | G32: 2597 | H32: 4259 | I32: 4702 | J32: =J30-J31 -> 5027.3701 | K32: =K30-K31 -> 5306.837 | L32: =L30-L31 -> 5581.4743 | M32: =M30-M31 -> 5854.2513 | N32: =N30-N31 -> 6140.2115
B33: - Preferred Dividends | C33: 0 | D33: 0 | E33: 0 | F33: 0 | G33: 0 | H33: 0 | I33: 0 | J33: 0 | K33: 0 | L33: 0 | M33: 0 | N33: 0
B34: - Other Adjustments | C34: 0 | D34: 0 | E34: 0 | F34: 0 | G34: 0 | H34: 0 | I34: 0 | J34: 0 | K34: 0 | L34: 0 | M34: 0 | N34: 0
B35: Net Income Avail to Common, GAAP | C35: 2747 | D35: 2983 | E35: 3260 | F35: 1243 | G35: 2597 | H35: 4259 | I35: 4702 | J35: =J32-SUM(J33:J34) -> 5027.3701 | K35: =K32-SUM(K33:K34) -> 5306.837 | L35: =L32-SUM(L33:L34) -> 5581.4743 | M35: =M32-SUM(M33:M34) -> 5854.2513 | N35: =N32-SUM(N33:N34) -> 6140.2115
B51: Reference Items
B52: Accounting Standard | C52: IAS/IFRS | D52: IAS/IFRS | E52: IAS/IFRS | F52: IAS/IFRS | G52: IAS/IFRS | H52: IAS/IFRS | I52: IAS/IFRS
B53: EBITDA | C53: 6532 | D53: 7074 | E53: 8492 | F53: 5776 | G53: 7644 | H53: 10079 | I53: 11758 | J53: 12462.938 | K53: 13116.188
B54: EBITDA Margin (T12M) | C54: 15.98 | D54: 16.0219 | E54: 17.4188 | F54: 13.1482 | G54: 15.2935 | H54: 16.1873 | I54: 16.8893 | J54: 17.335475 | K54: 17.656537
B55: EBITA | C55: 5547 | D55: 6149 | E55: 6844 | F55: 4000 | G55: 5858 | H55: 8136 | I55: 9771
B56: EBIT | C56: 4404 | D56: 4832 | E56: 5452 | F56: 2605 | G56: 4425 | H56: 6466 | I56: 7959 | J56: 8613.059 | K56: 9088.471
B57: Operating Margin | C57: 10.774 | D57: 10.944 | E57: 11.1831 | F57: 5.9299 | G57: 8.8532 | H57: 10.3846 | I57: 11.4324 | J57: 11.980439 | K57: 12.23457
B58: Profit Margin | C58: 6.7203 | D58: 6.7562 | E58: 6.6869 | F58: 2.8295 | G58: 5.1959 | H58: 6.8401 | I58: 6.754 | J58: 6.8648891 | K58: 7.1031516
...

Sheet Segment Rev+OPI build
W4: In Millions of EUR except Per Share | Y4: FY 2014 | Z4: FY 2015 | AA4: FY 2016 | AB4: FY 2017 | AC4: FY 2018 | AD4: FY 2019 | AE4: FY 2020 | AF4: FY 2021 | AG4: FY 2022 | AH4: FY 2023 | AI4: FY 2024 Est | AJ4: FY 2025 Est | AK4: FY 2026 Est | AL4: FY 2027 Est | AM4: FY 2028 Est
W5: 12 Months Ending
W6: Concessions
W7: Revenue | Y7: =SUM(Y8,Y10,Y14) -> 5823 | Z7: =SUM(Z8,Z10,Z14) -> 5803 | AA7: =SUM(AA8,AA10,AA14) -> 6297.98 | AB7: =SUM(AB8,AB10,AB14) -> 6944.6 | AC7: =SUM(AC8,AC10,AC14) -> 7255.58 | AD7: =SUM(AD8,AD10,AD14) -> 8544.58 | AE7: =SUM(AE8,AE10,AE14) -> 5837.8 | AF7: =SUM(AF8,AF10,AF14) -> 7047 | ... AM7: =SUM(AM8,AM10,AM14) -> 13710.743
W8: Road | Y8: 4743 | Z8: 4881 | AA8: 5111.49 | AB8: 5277.3 | AC8: 5356 | AD8: 5594.58 | AE8: 4612.8 | AF8: 5550 | AG8: 6003 | AH8: 6324 | AI8: =AH8*(1+AI9) -> 6513.72 | AJ8: =AI8*(1+AJ9) -> 6709.1316 | AK8: =AJ8*(1+AK9) -> 6910.4055 | AL8: =AK8*(1+AL9) -> 7117.7177 | AM8: =AL8*(1+AM9) -> 7331.2492
W9: %growth | Z9: =(Z8-Y8)/Y8 -> 0.029095509 | AA9: =(AA8-Z8)/Z8 -> 0.047221881 | AB9: =(AB8-AA8)/AA8 -> 0.032438682 | AC9: =(AC8-AB8)/AB8 -> 0.014912929 | AD9: =(AD8-AC8)/AC8 -> 0.044544436 | AE9: =(AE8-AD8)/AD8 -> -0.1754877 | AF9: =(AF8-AE8)/AE8 -> 0.20317378 | AG9: =(AG8-AF8)/AF8 -> 0.081621622 | AH9: =(AH8-AG8)/AG8 -> 0.053473263 | AI9: 0.03 | AJ9: 0.03 | AK9: 0.03 | AL9: 0.03 | AM9: 0.03
W10: Air | Y10: 717 | Z10: 820 | AA10: 1055.49 | AB10: 1409 | AC10: 1601.58 | AD10: 2631 | AE10: 990 | AF10: 1188 | AG10: 2679 | AH10: 3947 | AI10: =AH10*(1+AI11) -> 4223.29 | AJ10: =AI10*(1+AJ11) -> 4518.9203 | AK10: =AJ10*(1+AK11) -> 4835.2447 | AL10: =AK10*(1+AL11) -> 5173.7119 | AM10: =AL10*(1+AM11) -> 5535.8717
W11: %growth | Z11: =(Z10-Y10)/Y10 -> 0.14365411 | AA11: =(AA10-Z10)/Z10 -> 0.28718293 | AB11: =(AB10-AA10)/AA10 -> 0.33492501 | AC11: =(AC10-AB10)/AB10 -> 0.1366785 | AD11: =(AD10-AC10)/AC10 -> 0.64275278 | AE11: =(AE10-AD10)/AD10 -> -0.62371722 | AF11: =(AF10-AE10)/AE10 -> 0.2 | AG11: =(AG10-AF10)/AF10 -> 1.2550505 | AH11: =(AH10-AG10)/AG10 -> 0.47331094 | AI11: 0.07 | AJ11: 0.07 | AK11: 0.07 | AL11: 0.07 | AM11: 0.07
W12: Park
W13: %growth
W14: Other | Y14: 363 | Z14: 102 | AA14: 131 | AB14: 258.3 | AC14: 298 | AD14: 319 | AE14: 235 | AF14: 309 | AG14: 479 | AH14: 661 | AI14: =AH14*(1+AI15) -> 694.05 | AJ14: =AI14*(1+AJ15) -> 728.7525 | AK14: =AJ14*(1+AK15) -> 765.19013 | AL14: =AK14*(1+AL15) -> 803.44963 | AM14: =AL14*(1+AM15) -> 843.62211
W15: %growth | Z15: =(Z14-Y14)/Y14 -> -0.71900826 | AA15: =(AA14-Z14)/Z14 -> 0.28431373 | AB15: =(AB14-AA14)/AA14 -> 0.97175573 | AC15: =(AC14-AB14)/AB14 -> 0.15369725 | AD15: =(AD14-AC14)/AC14 -> 0.070469799 | AE15: =(AE14-AD14)/AD14 -> -0.26332288 | AF15: =(AF14-AE14)/AE14 -> 0.31489362 | AG15: =(AG14-AF14)/AF14 -> 0.55016181 | AH15: =(AH14-AG14)/AG14 -> 0.37995825 | AI15: 0.05 | AJ15: 0.05 | AK15: 0.05 | AL15: 0.05 | AM15: 0.05
W16: 0
W17: Operating margin | AA17: =AA18/AA7 -> 0.4688805 | AB17: =AB18/AB7 -> 0.46813351 | AC17: =AC18/AC7 -> 0.47260178 | AD17: =AD18/AD7 -> 0.46684565 | AE17: =AE18/AE7 -> 0.27167769 | AF17: =AF18/AF7 -> 0.38072939 | AG17: =AG18/AG7 -> 0.4554088 | AH17: =AH18/AH7 -> 0.49149286 | AI17: 0.48 | AJ17: 0.48 | AK17: 0.48 | AL17: 0.48 | AM17: 0.48
W18: Operating Income | AA18: 2953 | AB18: 3251 | AC18: 3429 | AD18: 3989 | AE18: 1586 | AF18: 2683 | AG18: 4172 | AH18: 5373 | AI18: =AI17*AI7 -> 5486.9088 | AJ18: =AJ17*AJ7 -> 5739.2661 | AK18: =AK17*AK7 -> 6005.2034 | AL18: =AL17*AL7 -> 6285.542 | AM18: =AM17*AM7 -> 6581.1567
W21: VINCI Immobilier & Holding Companies
W22: Revenue | Y22: 587 | Z22: 707 | AA22: 774 | AB22: 896 | AC22: 1104 | AD22: 1320 | AE22: 1191 | AF22: 2197 | AG22: 2113 | AH22: 2011 | AI22: =AH22*(1+AI23) -> 1005.5 | AJ22: =AI22*(1+AJ23) -> 1005.5 | AK22: =AJ22*(1+AK23) -> 1106.05 | AL22: =AK22*(1+AL23) -> 1216.655 | AM22: =AL22*(1+AM23) -> 1338.3205
P23: =AI7/AI54 -> 0.15872641 | Q23: =AH18/AH56 -> 0.64293407 | W23: % growth | Z23: =(Z22-Y22)/Y22 -> 0.2044293 | AA23: =(AA22-Z22)/Z22 -> 0.09476662 | AB23: =(AB22-AA22)/AA22 -> 0.15762274 | AC23: =(AC22-AB22)/AB22 -> 0.23214286 | AD23: =(AD22-AC22)/AC22 -> 0.19565217 | AE23: =(AE22-AD22)/AD22 -> -0.097727273 | AF23: =(AF22-AE22)/AE22 -> 0.84466835 | AG23: =(AG22-AF22)/AF22 -> -0.038233955 | AH23: =(AH22-AG22)/AG22 -> -0.048272598 | AI23: -0.5 | AJ23: 0 | AK23: 0.1 | AL23: 0.1 | AM23: 0.1
W24: Operating Margin | Y24: =Y25/Y22 -> 0.19080068 | Z24: =Z25/Z22 -> 0.12729844 | AA24: =AA25/AA22 -> 0.087855297 | AB24: =AB25/AB22 -> 0.13058036 | AC24: =AC25/AC22 -> 0.086050725 | AD24: =AD25/AD22 -> 0.06969697 | AE24: =AE25/AE22 -> 0.023509656 | AF24: =AF25/AF22 -> 0.038689122 | ... AH24: =AH25/AH22 -> -0.060666335 | AI24: 0.04 | AJ24: 0.04 | AK24: 0.04 | AL24: 0.04 | AM24: 0.04
W25: Operating Income | Y25: 112 | Z25: 90 | AA25: 68 | AB25: 117 | AC25: 95 | AD25: 92 | AE25: 28 | AF25: 85 | AG25: 0 | AH25: -122 | AI25: =AI24*AI22 -> 40.22 | AJ25: =AJ24*AJ22 -> 40.22 | AK25: =AK24*AK22 -> 44.242 | AL25: =AL24*AL22 -> 48.6662 | AM25: =AM24*AM22 -> 53.53282
W28: Cobra IS
W29: Revenue | AG29: 5520 | AH29: 6495 | AI29: =AH29*(1+AI30) -> 6884.7 | AJ29: =AI29*(1+AJ30) -> 7297.782 | AK29: =AJ29*(1+AK30) -> 7735.6489 | AL29: =AK29*(1+AL30) -> 8199.7879 | AM29: =AL29*(1+AM30) -> 8691.7751
W30: %growth | AH30: =(AH29-AG29)/AG29 -> 0.17663043 | AI30: 0.06 | AJ30: 0.06 | AK30: 0.06 | AL30: 0.06 | AM30: 0.06
W31: Operating Margin | AG31: =AG32/AG29 -> 0.074456522 | AH31: =AH32/AH29 -> 0.075442648 | AI31: 0.075 | AJ31: 0.075 | AK31: 0.075 | AL31: 0.075 | AM31: 0.075
W32: Operating Income | AG32: 411 | AH32: 490 | AI32: =AI31*AI29 -> 516.3525 | AJ32: =AJ31*AJ29 -> 547.33365 | AK32: =AK31*AK29 -> 580.17367 | AL32: =AL31*AL29 -> 614.98409 | AM32: =AM31*AM29 -> 651.88313
W35: VINCI Construction
W36: Revenue | Y36: 15419 | Z36: 14491 | AA36: 13681 | AB36: 13960 | AC36: 14231 | AD36: 14926 | AE36: 23149 | AF36: 26282 | AG36: 29252 | AH36: 31459 | AI36: =AH36*(1+AI37) -> 32402.77 | AJ36: =AI36*(1+AJ37) -> 33374.853 | AK36: =AJ36*(1+AK37) -> 34376.099 | AL36: =AK36*(1+AL37) -> 35407.382 | AM36: =AL36*(1+AM37) -> 36469.603
W37: % growth | Z37: =(Z36-Y36)/Y36 -> -0.060185485 | AA37: =(AA36-Z36)/Z36 -> -0.055896764 | AB37: =(AB36-AA36)/AA36 -> 0.020393246 | AC37: =(AC36-AB36)/AB36 -> 0.019412607 | AD37: =(AD36-AC36)/AC36 -> 0.048837046 | AE37: =(AE36-AD36)/AD36 -> 0.55091786 | AF37: =(AF36-AE36)/AE36 -> 0.13534062 | AG37: =(AG36-AF36)/AF36 -> 0.1130051 | AH37: =(AH36-AG36)/AG36 -> 0.075447833 | AI37: =0.03 -> 0.03 | AJ37: =0.03 -> 0.03 | AK37: =0.03 -> 0.03 | AL37: =0.03 -> 0.03 | AM37: =0.03 -> 0.03
W38: Operating Margin | Y38: =Y39/Y36 -> 0.020688761 | Z38: =Z39/Z36 -> 0.017045062 | AA38: =AA39/AA36 -> 0.024121044 | AB38: =AB39/AB36 -> 0.023137536 | AC38: =AC39/AC36 -> 0.028107652 | AD38: =AD39/AD36 -> 0.026530886 | AE38: =AE39/AE36 -> 0.020303253 | AF38: =AF39/AF36 -> 0.036831291 | ... AH38: =AH39/AH36 -> 0.040052131 | AI38: 0.04 | AJ38: 0.04 | AK38: 0.04 | AL38: 0.04 | AM38: 0.04
W39: Operating Income | Y39: 319 | Z39: 247 | AA39: 330 | AB39: 323 | AC39: 400 | AD39: 396 | AE39: 470 | AF39: 968 | AG39: 1100 | AH39: 1260 | AI39: =AI38*AI36 -> 1296.1108 | AJ39: =AJ38*AJ36 -> 1334.9941 | AK39: =AK38*AK36 -> 1375.0439 | AL39: =AL38*AL36 -> 1416.2953 | AM39: =AM38*AM36 -> 1458.7841
W44: Energy
W45: Revenue | Y45: 9309 | Z45: 10180 | AA45: 10200 | AB45: 10759 | AC45: 12603 | AD45: 13749 | AE45: 13661 | AF45: 15097 | AG45: 16748 | AH45: 19327 | AI45: =AH45*(1+AI46) -> 20293.35 | AJ45: =AI45*(1+AJ46) -> 21308.018 | AK45: =AJ45*(1+AK46) -> 22373.418 | AL45: =AK45*(1+AL46) -> 23492.089 | AM45: =AL45*(1+AM46) -> 24666.694
W46: % growth | Z46: =(Z45-Y45)/Y45 -> 0.093565367 | AA46: =(AA45-Z45)/Z45 -> 0.0019646365 | AB46: =(AB45-AA45)/AA45 -> 0.054803922 | AC46: =(AC45-AB45)/AB45 -> 0.17139139 | AD46: =(AD45-AC45)/AC45 -> 0.090930731 | AE46: =(AE45-AD45)/AD45 -> -0.0064004655 | AF46: =(AF45-AE45)/AE45 -> 0.10511676 | AG46: =(AG45-AF45)/AF45 -> 0.10935948 | AH46: =(AH45-AG45)/AG45 -> 0.15398854 | AI46: 0.05 | AJ46: 0.05 | AK46: 0.05 | AL46: 0.05 | AM46: 0.05
W47: Operating Margin | Y47: =Y48/Y45 -> 0.052314964 | Z47: =Z48/Z45 -> 0.051768173 | AA47: =AA48/AA45 -> 0.056960784 | AB47: =AB48/AB45 -> 0.050934102 | AC47: =AC48/AC45 -> 0.057684678 | AD47: =AD48/AD45 -> 0.060149829 | AE47: =AE48/AE45 -> 0.056584437 | AF47: =AF48/AF45 -> 0.065244751 | ... AH47: =AH48/AH45 -> 0.070160915 | AI47: 0.07 | AJ47: 0.07 | AK47: 0.07 | AL47: 0.07 | AM47: 0.07
W48: Operating Income | Y48: 487 | Z48: 527 | AA48: 581 | AB48: 548 | AC48: 727 | AD48: 827 | AE48: 773 | AF48: 985 | AG48: 1142 | AH48: 1356 | AI48: =AI47*AI45 -> 1420.5345 | AJ48: =AJ47*AJ45 -> 1491.5612 | AK48: =AK47*AK45 -> 1566.1393 | AL48: =AL47*AL45 -> 1644.4463 | AM48: =AM47*AM45 -> 1726.6686
W53: Group
W54: Revenue | Y54: =SUM(Y45,Y36,Y22,Y7,Y29) -> 31138 | Z54: =SUM(Z45,Z36,Z22,Z7,Z29) -> 31181 | AA54: =SUM(AA45,AA36,AA22,AA7,AA29) -> 30952.98 | AB54: =SUM(AB45,AB36,AB22,AB7,AB29) -> 32559.6 | AC54: =SUM(AC45,AC36,AC22,AC7,AC29) -> 35193.58 | AD54: =SUM(AD45,AD36,AD22,AD7,AD29) -> 38539.58 | AE54: =SUM(AE45,AE36,AE22,AE7,AE29) -> 43838.8 | AF54: =SUM(AF45,AF36,AF22,AF7,AF29) -> 50623 | ... AM54: =SUM(AM45,AM36,AM22,AM7,AM29) -> 84877.136
W55: % growth | AH55: =(AH54-AG54)/AG54 -> 0.11832341 | AI55: =(AI54-AH54)/AH54 -> 0.025537993 | AJ55: =(AJ54-AI54)/AI54 -> 0.040623208 | AK55: =(AK54-AJ54)/AJ54 -> 0.042153386 | AL55: =(AL54-AK54)/AK54 -> 0.04236427 | AM55: =(AM54-AL54)/AL54 -> 0.042578415
W56: Operating Income | AH56: =AH48+AH39+AH32+AH25+AH18 -> 8357 | AI56: =AI48+AI39+AI32+AI25+AI18 -> 8760.1266 | AJ56: =AJ48+AJ39+AJ32+AJ25+AJ18 -> 9153.3751 | AK56: =AK48+AK39+AK32+AK25+AK18 -> 9570.8023 | AL56: =AL48+AL39+AL32+AL25+AL18 -> 10009.934 | AM56: =AM48+AM39+AM32+AM25+AM18 -> 10472.025
W57: Operating Margin | AH57: =AH56/AH54 -> 0.1190049 | AI57: =AI56/AI54 -> 0.12163906 | AJ57: =AJ56/AJ54 -> 0.1221379 | AK57: =AK56/AK54 -> 0.12254226 | AL57: =AL56/AL54 -> 0.12295586 | AM57: =AM56/AM54 -> 0.12337864

Sheet OrderBook
F19: ="2014"&" Q1" -> 2014 Q1 | G19: ="2014"&" Q2" -> 2014 Q2 | H19: ="2014"&" Q3" -> 2014 Q3 | I19: ="2014"&" Q4" -> 2014 Q4 | J19: ="2015"&" Q1" -> 2015 Q1 | K19: ="2015"&" Q2" -> 2015 Q2 | L19: ="2015"&" Q3" -> 2015 Q3 | M19: ="2015"&" Q4" -> 2015 Q4 | N19: ="2016"&" Q1" -> 2016 Q1 | O19: ="2016"&" Q2" -> 2016 Q2 | P19: ="2016"&" Q3" -> 2016 Q3 | Q19: ="2016"&" Q4" -> 2016 Q4 | R19: ="2017"&" Q1" -> 2017 Q1 | S19: ="2017"&" Q2" -> 2017 Q2 | T19: ="2017"&" Q3" -> 2017 Q3 | U19: ="2017"&" Q4" -> 2017 Q4 | V19: ="2018"&" Q1" -> 2018 Q1 | W19: ="2018"&" Q2" -> 2018 Q2 | X19: ="2018"&" Q3" -> 2018 Q3 | Y19: ="2018"&" Q4" -> 2018 Q4 | Z19: ="2019"&" Q1" -> 2019 Q1 | AA19: ="2019"&" Q2" -> 2019 Q2 | AB19: ="2019"&" Q3" -> 2019 Q3 | AC19: ="2019"&" Q4" -> 2019 Q4 | AD19: ="2020"&" Q1" -> 2020 Q1 | AE19: ="2020"&" Q2" -> 2020 Q2 | AF19: ="2020"&" Q3" -> 2020 Q3 | AG19: ="2020"&" Q4" -> 2020 Q4 | AH19: ="2021"&" Q1" -> 2021 Q1 | AI19: ="2021"&" Q2" -> 2021 Q2 | AJ19: ="2021"&" Q3" -> 2021 Q3 | AK19: ="2021"&" Q4" -> 2021 Q4 | AL19: ="2022"&" Q1" -> 2022 Q1 | AM19: ="2022"&" Q2" -> 2022 Q2 | AN19: ="2022"&" Q3" -> 2022 Q3 | AO19: ="2022"&" Q4" -> 2022 Q4 | AP19: ="2023"&" Q1" -> 2023 Q1 | AQ19: ="2023"&" Q2" -> 2023 Q2 | AR19: ="2023"&" Q3" -> 2023 Q3 | AS19: ="2023"&" Q4" -> 2023 Q4 | AT19: 2024 Q1
E20: Vinci Energies Order Book | F20: 6800 | G20: 6600 | H20: 6400 | I20: 6300 | J20: 6600 | K20: 6800 | L20: 6500 | M20: 6100 | N20: 6600 | O20: 6400 | P20: 6200 | Q20: 5900 | R20: 6900 | S20: 7000 | T20: 7100 | U20: 6700 | V20: 8700 | W20: 8700 | X20: 8600 | Y20: 8400 | Z20: 9300 | AA20: 9400 | AB20: 9500 | AC20: 9100 | AD20: 10200 | AE20: 10200 | AF20: 10200 | AG20: 9900 | AH20: 10900 | AI20: 11200 | AJ20: 11400 | AK20: 11000 | AL20: 12200 | AM20: 12700 | AN20: 12600 | AO20: 12400 | AP20: 14500 | AQ20: 14700 | AR20: 14700 | AS20: 14300 | AT20: 16000
E21: Cobra IS Order Book | AL21: 8400 | AM21: 9300 | AN21: 11200 | AO21: 11100 | AP21: 11500 | AQ21: 13300 | AR21: 14900 | AS21: 14400 | AT21: 16700
E22: Vinci Construction Order Book | F22: 23900 | G22: 22900 | H22: 22300 | I22: 21600 | J22: 22500 | K22: 21900 | L22: 22000 | M22: 21700 | N22: 17000 | O22: 22800 | P22: 21700 | Q22: 21500 | R22: 23300 | S22: 23700 | T22: 23500 | U22: 22600 | V22: 24000 | W22: 24000 | X22: 24200 | Y22: 24700 | Z22: 25600 | AA22: 26800 | AB22: 27000 | AC22: 27400 | AD22: 27600 | AE22: 32700 | AF22: 32600 | AG22: 32500 | AH22: 35000 | AI22: 34800 | AJ22: 34000 | AK22: 33400 | AL22: 34300 | AM22: 34300 | AN22: 33600 | AO22: 33800 | AP22: 34300 | AQ22: 33600 | AR22: 33600 | AS22: 32700 | AT22: 33900
F30: ="2014"&" Q1" -> 2014 Q1 | G30: ="2014"&" Q2" -> 2014 Q2 | H30: ="2014"&" Q3" -> 2014 Q3 | I30: ="2014"&" Q4" -> 2014 Q4 | J30: ="2015"&" Q1" -> 2015 Q1 | K30: ="2015"&" Q2" -> 2015 Q2 | L30: ="2015"&" Q3" -> 2015 Q3 | M30: ="2015"&" Q4" -> 2015 Q4 | N30: ="2016"&" Q1" -> 2016 Q1 | O30: ="2016"&" Q2" -> 2016 Q2 | P30: ="2016"&" Q3" -> 2016 Q3 | Q30: ="2016"&" Q4" -> 2016 Q4 | R30: ="2017"&" Q1" -> 2017 Q1 | S30: ="2017"&" Q2" -> 2017 Q2 | T30: ="2017"&" Q3" -> 2017 Q3 | U30: ="2017"&" Q4" -> 2017 Q4 | V30: ="2018"&" Q1" -> 2018 Q1 | W30: ="2018"&" Q2" -> 2018 Q2 | X30: ="2018"&" Q3" -> 2018 Q3 | Y30: ="2018"&" Q4" -> 2018 Q4 | Z30: ="2019"&" Q1" -> 2019 Q1 | AA30: ="2019"&" Q2" -> 2019 Q2 | AB30: ="2019"&" Q3" -> 2019 Q3 | AC30: ="2019"&" Q4" -> 2019 Q4 | AD30: ="2020"&" Q1" -> 2020 Q1 | AE30: ="2020"&" Q2" -> 2020 Q2 | AF30: ="2020"&" Q3" -> 2020 Q3 | AG30: ="2020"&" Q4" -> 2020 Q4 | AH30: ="2021"&" Q1" -> 2021 Q1 | AI30: ="2021"&" Q2" -> 2021 Q2 | AJ30: ="2021"&" Q3" -> 2021 Q3 | AK30: ="2021"&" Q4" -> 2021 Q4 | AL30: ="2022"&" Q1" -> 2022 Q1 | AM30: ="2022"&" Q2" -> 2022 Q2 | AN30: ="2022"&" Q3" -> 2022 Q3 | AO30: ="2022"&" Q4" -> 2022 Q4 | AP30: ="2023"&" Q1" -> 2023 Q1 | AQ30: ="2023"&" Q2" -> 2023 Q2 | AR30: ="2023"&" Q3" -> 2023 Q3 | AS30: ="2023"&" Q4" -> 2023 Q4 | AT30: 2024 Q1
E31: Energies YoY Change | J31: =(J20-F20)/F20 -> -0.029411765 | K31: =(K20-G20)/G20 -> 0.03030303 | L31: =(L20-H20)/H20 -> 0.015625 | M31: =(M20-I20)/I20 -> -0.031746032 | N31: =(N20-J20)/J20 -> 0 | O31: =(O20-K20)/K20 -> -0.058823529 | P31: =(P20-L20)/L20 -> -0.046153846 | Q31: =(Q20-M20)/M20 -> -0.032786885 | ... AT31: =(AT20-AP20)/AP20 -> 0.10344828
E32: Cobra IS YoY Change | AP32: =(AP21-AL21)/AL21 -> 0.36904762 | AQ32: =(AQ21-AM21)/AM21 -> 0.43010753 | AR32: =(AR21-AN21)/AN21 -> 0.33035714 | AS32: =(AS21-AO21)/AO21 -> 0.2972973 | AT32: =(AT21-AP21)/AP21 -> 0.45217391
E33: Construction YoY Change | J33: =(J22-F22)/F22 -> -0.058577406 | K33: =(K22-G22)/G22 -> -0.043668122 | L33: =(L22-H22)/H22 -> -0.013452915 | M33: =(M22-I22)/I22 -> 0.0046296296 | N33: =(N22-J22)/J22 -> -0.24444444 | O33: =(O22-K22)/K22 -> 0.04109589 | P33: =(P22-L22)/L22 -> -0.013636364 | Q33: =(Q22-M22)/M22 -> -0.0092165899 | ... AT33: =(AT22-AP22)/AP22 -> -0.011661808
F35: ="2014"&" Q1" -> 2014 Q1 | G35: ="2014"&" Q2" -> 2014 Q2 | H35: ="2014"&" Q3" -> 2014 Q3 | I35: ="2014"&" Q4" -> 2014 Q4 | J35: ="2015"&" Q1" -> 2015 Q1 | K35: ="2015"&" Q2" -> 2015 Q2 | L35: ="2015"&" Q3" -> 2015 Q3 | M35: ="2015"&" Q4" -> 2015 Q4 | N35: ="2016"&" Q1" -> 2016 Q1 | O35: ="2016"&" Q2" -> 2016 Q2 | P35: ="2016"&" Q3" -> 2016 Q3 | Q35: ="2016"&" Q4" -> 2016 Q4 | R35: ="2017"&" Q1" -> 2017 Q1 | S35: ="2017"&" Q2" -> 2017 Q2 | T35: ="2017"&" Q3" -> 2017 Q3 | U35: ="2017"&" Q4" -> 2017 Q4 | V35: ="2018"&" Q1" -> 2018 Q1 | W35: ="2018"&" Q2" -> 2018 Q2 | X35: ="2018"&" Q3" -> 2018 Q3 | Y35: ="2018"&" Q4" -> 2018 Q4 | Z35: ="2019"&" Q1" -> 2019 Q1 | AA35: ="2019"&" Q2" -> 2019 Q2 | AB35: ="2019"&" Q3" -> 2019 Q3 | AC35: ="2019"&" Q4" -> 2019 Q4 | AD35: ="2020"&" Q1" -> 2020 Q1 | AE35: ="2020"&" Q2" -> 2020 Q2 | AF35: ="2020"&" Q3" -> 2020 Q3 | AG35: ="2020"&" Q4" -> 2020 Q4 | AH35: ="2021"&" Q1" -> 2021 Q1 | AI35: ="2021"&" Q2" -> 2021 Q2 | AJ35: ="2021"&" Q3" -> 2021 Q3 | AK35: ="2021"&" Q4" -> 2021 Q4 | AL35: ="2022"&" Q1" -> 2022 Q1 | AM35: ="2022"&" Q2" -> 2022 Q2 | AN35: ="2022"&" Q3" -> 2022 Q3 | AO35: ="2022"&" Q4" -> 2022 Q4 | AP35: ="2023"&" Q1" -> 2023 Q1 | AQ35: ="2023"&" Q2" -> 2023 Q2 | AR35: ="2023"&" Q3" -> 2023 Q3 | AS35: ="2023"&" Q4" -> 2023 Q4 | AT35: 2024 Q1
E36: Energies QoQ Change | G36: =(G20-F20)/F20 -> -0.029411765 | H36: =(H20-G20)/G20 -> -0.03030303 | I36: =(I20-H20)/H20 -> -0.015625 | J36: =(J20-I20)/I20 -> 0.047619048 | K36: =(K20-J20)/J20 -> 0.03030303 | L36: =(L20-K20)/K20 -> -0.044117647 | M36: =(M20-L20)/L20 -> -0.061538462 | N36: =(N20-M20)/M20 -> 0.081967213 | ... AT36: =(AT20-AS20)/AS20 -> 0.11888112
E37: Cobra IS QoQ Change | AM37: =(AM21-AL21)/AL21 -> 0.10714286 | AN37: =(AN21-AM21)/AM21 -> 0.20430108 | AO37: =(AO21-AN21)/AN21 -> -0.0089285714 | AP37: =(AP21-AO21)/AO21 -> 0.036036036 | AQ37: =(AQ21-AP21)/AP21 -> 0.15652174 | AR37: =(AR21-AQ21)/AQ21 -> 0.12030075 | AS37: =(AS21-AR21)/AR21 -> -0.033557047 | AT37: =(AT21-AS21)/AS21 -> 0.15972222
E38: Construction QoQ Change | G38: =(G22-F22)/F22 -> -0.041841004 | H38: =(H22-G22)/G22 -> -0.026200873 | I38: =(I22-H22)/H22 -> -0.031390135 | J38: =(J22-I22)/I22 -> 0.041666667 | K38: =(K22-J22)/J22 -> -0.026666667 | L38: =(L22-K22)/K22 -> 0.00456621 | M38: =(M22-L22)/L22 -> -0.013636364 | N38: =(N22-M22)/M22 -> -0.21658986 | ... AT38: =(AT22-AS22)/AS22 -> 0.036697248

Sheet SOTP
A2: Business Line | B2: 2025 EBIT | C2: Multiple/Method | D2: Value | E2: % SOTP
A3: Vinci Construction | B3: ='Segment Rev+OPI build'!AJ39 -> 1334.9941 | C3: 6 | D3: =(B3*C3) -> 8009.9647 | E3: =D3/$B$25 -> 0.086465727
A4: Vinci Energies | B4: ='Segment Rev+OPI build'!AJ48 -> 1491.5612 | C4: 11 | D4: =(B4*C4) -> 16407.173 | E4: =D4/$B$25 -> 0.17711166
A5: Cobra IS - Contracting | B5: ='Segment Rev+OPI build'!AJ32 -> 547.33365 | C5: 11 | D5: =(B5*C5) -> 6020.6701 | E5: =D5/$B$25 -> 0.06499175
A6: Contracting | B6: =SUM(B3:B5) -> 3373.889 | D6: =SUM(D3:D5) -> 30437.808 | E6: =D6/$B$25 -> 0.32856914
B8: BV
A9: Immobilier | B9: 113 | C9: 1 | D9: =(B9*C9) -> 113 | E9: =D9/$B$25 -> 0.001219809
A11: Concessions
A12: Cofiroute | C12: DCF | D12: =B79 -> 6201.6781 | E12: =D12/$B$25 -> 0.066945688
A13: ASF | C13: DCF | D13: =B92 -> 18460.278 | E13: =D13/$B$25 -> 0.19927446
A14: ARCOUR | C14: DCF | D14: =B105 -> 996.15472 | E14: =D14/$B$25 -> 0.010753261
A15: Gatwick | C15: DCF | D15: =B120 -> 7743.8815 | E15: =D15/$B$25 -> 0.08359342
A16: ANA | C16: DCF | D16: =B135 -> 12576.652 | E16: =D16/$B$25 -> 0.13576207
A17: ADP | C17: MKT VAL | D17: 910 | E17: =D17/$B$25 -> 0.0098232407
A18: OMA | C18: MKT VAL | D18: 962 | E18: =D18/$B$25 -> 0.010384569
A19: Lyon Airport | C19: TRANS VAL | D19: 535 | E19: =D19/$B$25 -> 0.005775202
A20: Edinburgh Airport | C20: TRANS VAL | D20: 4233 | E20: =D20/$B$25 -> 0.045694262
A21: Northwest Parkway (Denver) | C21: TRANS VAL | D21: 1126 | E21: =D21/$B$25 -> 0.012154911
A22: Other concessions | B22: 609 | C22: 12 | D22: =B22*C22 -> 7308 | E22: =D22/$B$25 -> 0.078888179
A23: Polo Carmópolis | C23: TRANS VAL | D23: 1034 | E23: =D23/$B$25 -> 0.011161792
A25: EV | B25: =SUM(D6:D23) -> 92637.453
A26: Net Debt | B26: -15391
A27: Minority Interest | B27: -5200
A28: Equity Value | B28: =SUM(B25:B27) -> 72046.453
A29: Per Share | B29: =B28/575 -> 125.29818
B69: 2024 | C69: =B69+1 -> 2025 | D69: =C69+1 -> 2026 | E69: =D69+1 -> 2027 | F69: =E69+1 -> 2028 | G69: =F69+1 -> 2029 | H69: =G69+1 -> 2030 | I69: =H69+1 -> 2031 | J69: =I69+1 -> 2032 | ... L69: =K69+1 -> 2034
A70: Cofiroute
A71: Toll Revenue | B71: 1622 | C71: =(1+C72)*B71 -> 1656.062 | D71: =(1+D72)*C71 -> 1690.8393 | E71: =(1+E72)*D71 -> 1726.3469 | F71: =(1+F72)*E71 -> 1762.6002 | G71: =(1+G72)*F71 -> 1799.6148 | H71: =(1+H72)*G71 -> 1837.4067 | I71: =(1+I72)*H71 -> 1875.9923 | J71: =(1+J72)*I71 -> 1915.3881 | ... L71: =(1+L72)*K71 -> 1996.6791
A72: Growth % | C72: 0.021 | D72: 0.021 | E72: 0.021 | F72: 0.021 | G72: 0.021 | H72: 0.021 | I72: 0.021 | J72: 0.021 | K72: 0.021 | L72: 0.021
A73: EBITDA Margin | B73: 0.7 | C73: 0.7 | D73: 0.7 | E73: 0.7 | F73: 0.7 | G73: 0.7 | H73: 0.7 | I73: 0.7 | J73: 0.7 | K73: 0.7 | L73: 0.7
A74: EBITDA | B74: =B73*B71 -> 1135.4 | C74: =C73*C71 -> 1159.2434 | D74: =D73*D71 -> 1183.5875 | E74: =E73*E71 -> 1208.4428 | F74: =F73*F71 -> 1233.8201 | G74: =G73*G71 -> 1259.7304 | H74: =H73*H71 -> 1286.1847 | I74: =I73*I71 -> 1313.1946 | ... L74: =L73*L71 -> 1397.6754 | N74: WACC | O74: Tax Rate
A75: Capex % of Tolls | B75: =0.03 -> 0.03 | C75: =0.03 -> 0.03 | D75: =0.03 -> 0.03 | E75: =0.03 -> 0.03 | F75: =0.03 -> 0.03 | G75: =0.03 -> 0.03 | H75: =0.03 -> 0.03 | I75: =0.03 -> 0.03 | ... L75: =0.03 -> 0.03
A76: Capex | B76: =-B75*B71 -> -48.66 | C76: =-C75*C71 -> -49.68186 | D76: =-D75*D71 -> -50.725179 | E76: =-E75*E71 -> -51.790408 | F76: =-F75*F71 -> -52.878006 | G76: =-G75*G71 -> -53.988445 | H76: =-H75*H71 -> -55.122202 | I76: =-I75*I71 -> -56.279768 | ... L76: =-L75*L71 -> -59.900373 | N76: 0.069 | O76: =0.26 -> 0.26
A77: Tax | B77: =-(B74)*$O$76 -> -295.204 | C77: =-(C74)*$O$76 -> -301.40328 | D77: =-(D74)*$O$76 -> -307.73275 | E77: =-(E74)*$O$76 -> -314.19514 | F77: =-(F74)*$O$76 -> -320.79324 | G77: =-(G74)*$O$76 -> -327.5299 | H77: =-(H74)*$O$76 -> -334.40802 | I77: =-(I74)*$O$76 -> -341.43059 | ... L77: =-(L74)*$O$76 -> -363.3956
A78: CF | B78: =SUM(B74,B76,B77) -> 791.536 | C78: =SUM(C74,C76,C77) -> 808.15826 | D78: =SUM(D74,D76,D77) -> 825.12958 | E78: =SUM(E74,E76,E77) -> 842.4573 | F78: =SUM(F74,F76,F77) -> 860.1489 | G78: =SUM(G74,G76,G77) -> 878.21203 | H78: =SUM(H74,H76,H77) -> 896.65448 | I78: =SUM(I74,I76,I77) -> 915.48423 | ... L78: =SUM(L74,L76,L77) -> 974.3794
A79: NPV | B79: =NPV(N76,C78:L78) -> 6201.6781
A83: ASF | B83: =B69 -> 2024 | C83: =C69 -> 2025 | D83: =D69 -> 2026 | E83: =E69 -> 2027 | F83: =F69 -> 2028 | G83: =G69 -> 2029 | H83: =H69 -> 2030 | I83: =I69 -> 2031 | ... L83: =L69 -> 2034 | M83: =2035 -> 2035 | N83: 2036 | P83: WACC | Q83: Tax Rate
A84: Toll Revenues | B84: 4708 | C84: =(1+C85)*B84 -> 4802.16 | D84: =(1+D85)*C84 -> 4898.2032 | E84: =(1+E85)*D84 -> 4996.1673 | F84: =(1+F85)*E84 -> 5096.0906 | G84: =(1+G85)*F84 -> 5198.0124 | H84: =(1+H85)*G84 -> 5301.9727 | I84: =(1+I85)*H84 -> 5408.0121 | J84: =(1+J85)*I84 -> 4867.2109 | ... N84: =(1+N85)*M84 -> 2582.5616 | Q84: 0.26
A85: Growth % | C85: 0.02 | D85: 0.02 | E85: 0.02 | F85: 0.02 | G85: 0.02 | H85: 0.02 | I85: 0.02 | J85: -0.1 | K85: 0.02 | L85: 0.02 | M85: 0.02 | N85: -0.5
A86: EBITDA Margin | B86: 0.7 | C86: 0.7 | D86: 0.7 | E86: 0.7 | F86: 0.7 | G86: 0.7 | H86: 0.7 | I86: 0.7 | J86: 0.7 | K86: 0.7 | L86: 0.7 | M86: 0.7 | N86: 0.7
...
